Workbook
Name OLE_LINK41: Matrix!$U$13

Sheet Master Dashboard
A1: GAMMA WALL PROFILE | E1: SPX KING NODE — LIVE DASHBOARD | L1: ='King Node Model'!K26 -> Updated 17:39:36 | AM1: =MAX(MAX('King Node Model'!C29:C75),-MIN('King Node Model'!C29:C75)) -> 3137174 | AN1: ='King Node Model'!T22 -> 7825 | AO1: =MAX('King Node Model'!B29:B75) -> 4471438
A2: puts ◄ | B2: Hide unsafe | C2: ► calls | D2: offset | AM2: ='King Node Model'!B4 -> 7775.39 | AN2: ='King Node Model'!T23 -> 7770
A3: =IF(AND(ISNUMBER($AM3),$AM3<0,ISNUMBER($AO3),$AO$1>0),REPT("█",ROUND($AO3/$AO$1*26,0)),"") | B3: =TEXT(IF(IF('Level Engine'!$GJ$4=1,$AL3='Level Engine'!$GJ$3,AND($AL3-$AM$2>-2.5,$AL3-$AM$2<=2.5)),$AM$2,$AL3),"0")&IF($AL3=$AN$1," ★","")&IF($AL3=$AN$2," ★","")&IF($AL3=$AN$3," ◆","")&IF(AND(ISNUMBER($AN$4),$AL3=$AN$4)," Ⓕ","")&IF(OR(AND(ISNUMBER('Level Engine'!$BG$87),$AL3='Level Engine'!$BG$87),AND(ISNUMBER('Level Engine'!$BG$105),$AL3='Level Engine'!$BG$105))," ζ","")&IF(AND(ISNUMBER($AN$35),$AL3=$AN$35)," ⓏⒼ","")&IF(OR($AL3='Level Engine'!$CP$4,$AL3='Level Engine'!$CP$5,$AL3='Level Engine'!$CP$6,$AL3='Level Engine'!$CP$7)," ☄","")&IF(OR($AL3=$AN$5,$AL3=$AN$8)," ║1","")&IF(OR($AL3=$AN$6,$AL3=$AN$10)," ║2","")&IF(OR($AL3=$AN$7,$AL3=$AN$11)," ║3","")&IF(OR($AL3=$AN$13,$AL3=$AN$16)," ▣1","")&IF(OR($AL3=$AN$14,$AL3=$AN$17)," ▣2","")&IF(OR($AL3=$AN$15,$AL3=$AN$18)," ▣3","")&IF(AND(NOT(OR(AND(ISNUMBER(SEARCH("chop edge",$E$45)),IFERROR(ABS($AL3-'King Node Model'!$AL$42)<=5,FALSE),NOT(ISNUMBER(SEARCH("UNSAFE",$L$45)))),AND(ISNUMBER(SEARCH("chop edge",$E$46)),IFERROR(ABS($AL3-'King Node Model'!$AL$43)<=5,FALSE),NOT(ISNUMBER(SEARCH("UNSAFE",$L$46)))),AND(ISNUMBER(SEARCH("chop edge",$E$52)),IFERROR(ABS($AL3-'King Node Model'!$AL$49)<=5,FALSE),NOT(ISNUMBER(SEARCH("UNSAFE",$L$52)))),AND(ISNUMBER(SEARCH("chop edge",$E$53)),IFERROR(ABS($AL3-'King Node Model'!$AL$50)<=5,FALSE),NOT(ISNUMBER(SEARCH("UNSAFE",$L$53)))))),OR(AND(IFERROR(INDEX('Level Engine'!$IB$9:$IB$55,MATCH('King Node Model'!$AL$49,'Level Engine'!$AA$9:$AA$55,0)),0)<>1,$AL3=IFERROR(INDEX('Level Engine'!$AU$9:$AU$55,MATCH('King Node Model'!$AL$49,'Level Engine'!$AA$9:$AA$55,0)),""),IFERROR(INDEX('Level Engine'!$AU$9:$AU$55,MATCH('King Node Model'!$AL$49,'Level Engine'!$AA$9:$AA$55,0)),"")<>IFERROR(INDEX('Level Engine'!$AT$9:$AT$55,MATCH('King Node Model'!$AL$49,'Level Engine'!$AA$9:$AA$55,0)),"")),AND(IFERROR(INDEX('Level Engine'!$IB$9:$IB$55,MATCH('King Node Model'!$AL$50,'Level Engine'!$AA$9:$AA$55,0)),0)<>1,$AL3=IFERROR(INDEX('Level Engine'!$AU$9:$AU$55,MATCH('King Node Model'!$AL$50,'Level Engine'!$AA$9:$AA$55,0)),""),IFERROR(INDEX('Level Engine'!$AU$9:$AU$55,MATCH('King Node Model'!$AL$50,'Level Engine'!$AA$9:$AA$55,0)),"")<>IFERROR(INDEX('Level Engine'!$AT$9:$AT$55,MATCH('King Node Model'!$AL$50,'Level Engine'!$AA$9:$AA$55,0)),"")))),IF(OR('King Node Model'!$A$8="Neg",N('Level Engine'!$BG$72)=1),""," ⒷⒽ"),"")&IF(AND(NOT(OR(AND(ISNUMBER(SEARCH("chop edge",$E$45)),IFERROR(ABS($AL3-'King Node Model'!$AL$42)<=5,FALSE),NOT(ISNUMBER(SEARCH("UNSAFE",$L$45)))),AND(ISNUMBER(SEARCH("chop edge",$E$46)),IFERROR(ABS($AL3-'King Node Model'!$AL$43)<=5,FALSE),NOT(ISNUMBER(SEARCH("UNSAFE",$L$46)))),AND(ISNUMBER(SEARCH("chop edge",$E$52)),IFERROR(ABS($AL3-'King Node Model'!$AL$49)<=5,FALSE),NOT(ISNUMBER(SEARCH("UNSAFE",$L$52)))),AND(ISNUMBER(SEARCH("chop edge",$E$53)),IFERROR(ABS($AL3-'King Node Model'!$AL$50)<=5,FALSE),NOT(ISNUMBER(SEARCH("UNSAFE",$L$53)))))),OR(AND(IFERROR(INDEX('Level Engine'!$IB$9:$IB$55,MATCH('King Node Model'!$AL$42,'Level Engine'!$AA$9:$AA$55,0)),0)<>1,$AL3=IFERROR(INDEX('Level Engine'!$AT$9:$AT$55,MATCH('King Node Model'!$AL$42,'Level Engine'!$AA$9:$AA$55,0)),""),IFERROR(INDEX('Level Engine'!$AT$9:$AT$55,MATCH('King Node Model'!$AL$42,'Level Engine'!$AA$9:$AA$55,0)),"")<>IFERROR(INDEX('Level Engine'!$AU$9:$AU$55,MATCH('King Node Model'!$AL$42,'Level Engine'!$AA$9:$AA$55,0)),"")),AND(IFERROR(INDEX('Level Engine'!$IB$9:$IB$55,MATCH('King Node Model'!$AL$43,'Level Engine'!$AA$9:$AA$55,0)),0)<>1,$AL3=IFERROR(INDEX('Level Engine'!$AT$9:$AT$55,MATCH('King Node Model'!$AL$43,'Level Engine'!$AA$9:$AA$55,0)),""),IFERROR(INDEX('Level Engine'!$AT$9:$AT$55,MATCH('King Node Model'!$AL$43,'Level Engine'!$AA$9:$AA$55,0)),"")<>IFERROR(INDEX('Level Engine'!$AU$9:$AU$55,MATCH('King Node Model'!$AL$43,'Level Engine'!$AA$9:$AA$55,0)),"")))),IF(OR('King Node Model'!$A$8="Neg",N('Level Engine'!$BG$72)=1),""," ⒷⓁ"),"")&IF(OR(AND($AL3>='King Node Model'!$AM$17,$AL3<='King Node Model'!$AN$17,$AP$45="RASP"),AND($AL3>='King Node Model'!$AM$18,$AL3<='King Node Model'!$AN$18,$AP$46="RASP"),AND($AL3>='King Node Model'!$AM$19,$AL3<='King Node Model'!$AN$19,$AP$47="RASP"),AND($AL3>='King Node Model'!$AM$20,$AL3<='King Node Model'!$AN$20,$AP$52="RASP"),AND($AL3>='King Node Model'!$AM$21,$AL3<='King Node Model'!$AN$21,$AP$53="RASP"),AND($AL3>='King Node Model'!$AM$22,$AL3<='King Node Model'!$AN$22,$AP$54="RASP")),"","")&IF(IF('Level Engine'!$GJ$4=1,$AL3='Level Engine'!$GJ$3,AND($AL3-$AM$2>-2.5,$AL3-$AM$2<=2.5))," ◄","")&IF(IFERROR(INDEX('Level Engine'!$GV$9:$GV$55,MATCH($AL3,'Level Engine'!$AA$9:$AA$55,0)),0)=1," Ⓥ"&IF(IFERROR(INDEX('Level Engine'!$ET$9:$ET$55,MATCH($AL3,'Level Engine'!$AA$9:$AA$55,0)),0)=1,"+",""),"")&IF(OR(AND($AL3=$AN$38,IFERROR(INDEX('Level Engine'!$AN$9:$AN$55,MATCH($AL3,'Level Engine'!$AA$9:$AA$55,0)),0)<>1),$AL3=$AN$39)," ⊙","")&IF(AND(OR('King Node Model'!$A$8="Neg",N('Level Engine'!$BG$72)=1),ABS(MIN($AM$3:$AM$64))>MAX($AM$3:$AM$64),$AN$2<$AM$2,$AL3<$AM$2,ABS($AL3-$AN$2)<=5,IFERROR(VALUE(MID('King Node Model'!$K$26,FIND(":",'King Node Model'!$K$26)-2,2)),0)>=19,IFERROR(INDEX('Level Engine'!$EJ$9:$EJ$55,MATCH($AL3,'Level Engine'!$AA$9:$AA$55,0)),0)=0,$AN$3>$AM$2)," ⟲rev","")&IF($AL3='King Node Model'!$F$24," ⟂","")&$DJ3&IF(IFERROR(INDEX('Level Engine'!$EN$9:$EN$55,MATCH($AL3,'Level Engine'!$AA$9:$AA$55,0)),0)=1," Ⓟ"&IF(AND(OR('King Node Model'!$A$8="Neg",N('Level Engine'!$BG$72)=1),IFERROR(INDEX('Level Engine'!$AN$9:$AN$55,MATCH($AL3,'Level Engine'!$AA$9:$AA$55,0)),0)<>1)," NO-REV",""),"")&IF(AND(ISNUMBER($AL3),OR(AND(ISNUMBER(SEARCH("chop edge",$E$45)),$AL3='King Node Model'!$AL$42),AND(ISNUMBER(SEARCH("chop edge",$E$46)),$AL3='King Node Model'!$AL$43),AND(ISNUMBER(SEARCH("chop edge",$E$52)),$AL3='King Node Model'!$AL$49),AND(ISNUMBER(SEARCH("chop edge",$E$53)),$AL3='King Node Model'!$AL$50)))," ⒸⒺ","")&IF(AND('Level Engine'!$GJ$4=1,OR($AL3='Level Engine'!$GJ$1,$AL3='Level Engine'!$GJ$2)),"","")&IF(ABS(N(IFERROR(INDEX('Level Engine'!$AE$9:$AE$55,MATCH($AL3,'Level Engine'!$AA$9:$AA$55,0)),0)))>='Level Engine'!$BG$85,IF(N(IFERROR(INDEX('Level Engine'!$AE$9:$AE$55,MATCH($AL3,'Level Engine'!$AA$9:$AA$55,0)),0))>0," Δ+"," Δ−"),"")&IFERROR(IF(AND(ISNUMBER(MATCH($AL3,'Level Engine'!$AA$9:$AA$55,0)),ABS(N(IFERROR(INDEX('Level Engine'!$AE$9:$AE$55,MATCH($AL3,'Level Engine'!$AA$9:$AA$55,0)),0)))<'Level Engine'!$BG$85,ABS(N(IFERROR(INDEX('Level Engine'!$AE$9:$AE$55,MATCH($AL3,'Level Engine'!$AA$9:$AA$55,0)),0)))<=ABS(N(IFERROR(INDEX('Level Engine'!$AE$9:$AE$55,MATCH($AL3+5,'Level Engine'!$AA$9:$AA$55,0)),0))),ABS(N(IFERROR(INDEX('Level Engine'!$AE$9:$AE$55,MATCH($AL3,'Level Engine'!$AA$9:$AA$55,0)),0)))<=ABS(N(IFERROR(INDEX('Level Engine'!$AE$9:$AE$55,MATCH($AL3-5,'Level Engine'!$AA$9:$AA$55,0)),0))),OR(AND(ABS(N(IFERROR(INDEX('Level Engine'!$AE$9:$AE$55,MATCH($AL3+5,'Level Engine'!$AA$9:$AA$55,0)),0)))>='Level Engine'!$BG$85,ABS(N(IFERROR(INDEX('Level Engine'!$AE$9:$AE$55,MATCH($AL3,'Level Engine'!$AA$9:$AA$55,0)),0)))<='Level Engine'!$BG$88*ABS(N(IFERROR(INDEX('Level Engine'!$AE$9:$AE$55,MATCH($AL3+5,'Level Engine'!$AA$9:$AA$55,0)),0)))),AND(ABS(N(IFERROR(INDEX('Level Engine'!$AE$9:$AE$55,MATCH($AL3-5,'Level Engine'!$AA$9:$AA$55,0)),0)))>='Level Engine'!$BG$85,ABS(N(IFERROR(INDEX('Level Engine'!$AE$9:$AE$55,MATCH($AL3,'Level Engine'!$AA$9:$AA$55,0)),0)))<='Level Engine'!$BG$88*ABS(N(IFERROR(INDEX('Level Engine'!$AE$9:$AE$55,MATCH($AL3-5,'Level Engine'!$AA$9:$AA$55,0)),0)))))),IF(AND('King Node Model'!$A$8="Pos",N('Level Engine'!$BG$72)<>1),""," ∅"),""),"")&IF(IFERROR(INDEX('Level Engine'!$JD$9:$JD$55,MATCH($AL3,'Level Engine'!$AA$9:$AA$55,0)),"")="P"," P-OI",IF(IFERROR(INDEX('Level Engine'!$JD$9:$JD$55,MATCH($AL3,'Level Engine'!$AA$9:$AA$55,0)),"")="C"," C-OI","")) -> 7885 | C3: =IF(AND(ISNUMBER($AM3),$AM3>0,ISNUMBER($AO3),$AO$1>0),REPT("█",ROUND($AO3/$AO$1*26,0)),"") | D3: =IF(NOT(ISNUMBER($AL3)),"",IF(IFERROR(INDEX('Level Engine'!$FS$9:$FS$55,MATCH($AL3,'Level Engine'!$AA$9:$AA$55,0)),0)=1,"⊙","")) | E3: ="SPOT "&TEXT('King Node Model'!$B$4,"#,##0.0") -> SPOT 7,775.4 | G3: ="REGIME "&'King Node Model'!$A$8 -> REGIME Neg | I3: ="GAMMA FLIP "&TEXT('King Node Model'!$D$26,"0") -> GAMMA FLIP 7805 | K3: ="ZERO GAMMA "&IF(ISNUMBER('King Node Model'!$D$27),TEXT('King Node Model'!$D$27,"0"),"—") -> ZERO GAMMA 7775 | Q3: IV TRACKER | AL3: ='King Node Model'!A29 -> 7885 | AM3: ='King Node Model'!C29 -> 32827 | AN3: ='King Node Model'!B23 -> 7770 | AO3: ='King Node Model'!B29 -> 33280 | AY3: =IF(AND($B$2="Hide unsafe",$BB3=1),0,IF(AND(OR(AND(AND(ISNUMBER($AL3),OR(AND($AL3>=$AQ$22,$AL3<=$AR$22,$AS$22=1),$AL3=$AQ$22,$AL3=$AR$22,$AL3=$AQ$23,$AL3=$AR$23,$AL3=$AQ$24,$AL3=$AR$24),NOT(OR($AL3=$AN$5,$AL3=$AN$6,$AL3=$AN$7,$AL3=$AN$8,$AL3=$AN$10,$AL3=$AN$11))),NOT(OR(AND('King Node Model'!$P$13="Up",OR($AL3=$AQ$22,$AL3=$AQ$23,$AL3=$AQ$24,$AL3='King Node Model'!$AM$20,$AL3='King Node Model'!$AM$21,$AL3='King Node Model'!$AM$22),OR(AND('King Node Model'!$B$23-$AL3>=0,'King Node Model'!$B$23-$AL3<=5),AND('King Node Model'!$C$23-$AL3>=0,'King Node Model'!$C$23-$AL3<=5))),AND('King Node Model'!$P$13="Down",OR($AL3=$AR$22,$AL3=$AR$23,$AL3=$AR$24,$AL3='King Node Model'!$AN$20,$AL3='King Node Model'!$AN$21,$AL3='King Node Model'!$AN$22),OR(AND($AL3-'King Node Model'!$B$23>=0,$AL3-'King Node Model'!$B$23<=5),AND($AL3-'King Node Model'!$C$24>=0,$AL3-'King Node Model'!$C$24<=5)))))),AND(AND(ISNUMBER($AL3),OR(AND($AL3>=$AQ$22,$AL3<=$AR$22,$AS$22=1),$AL3=$AQ$22,$AL3=$AR$22,$AL3=$AQ$23,$AL3=$AR$23,$AL3=$AQ$24,$AL3=$AR$24,$AL3='King Node Model'!$AL$42,$AL3='King Node Model'!$AL$43),OR($AL3=$AN$5,$AL3=$AN$6,$AL3=$AN$7,$AL3=$AN$8,$AL3=$AN$10,$AL3=$AN$11)),NOT(OR(AND('King Node Model'!$P$13="Up",OR($AL3=$AQ$22,$AL3=$AQ$23,$AL3=$AQ$24,$AL3='King Node Model'!$AM$20,$AL3='King Node Model'!$AM$21,$AL3='King Node Model'!$AM$22),OR(AND('King Node Model'!$B$23-$AL3>=0,'King Node Model'!$B$23-$AL3<=5),AND('King Node Model'!$C$23-$AL3>=0,'King Node Model'!$C$23-$AL3<=5))),AND('King Node Model'!$P$13="Down",OR($AL3=$AR$22,$AL3=$AR$23,$AL3=$AR$24,$AL3='King Node Model'!$AN$20,$AL3='King Node Model'!$AN$21,$AL3='King Node Model'!$AN$22),OR(AND($AL3-'King Node Model'!$B$23>=0,$AL3-'King Node Model'!$B$23<=5),AND($AL3-'King Node Model'!$C$24>=0,$AL3-'King Node Model'!$C$24<=5)))))),AND(AND(ISNUMBER($AL3),OR(AND($AL3>='King Node Model'!$AM$20,$AL3<='King Node Model'!$AN$20,$AS$23=1),$AL3='King Node Model'!$AM$20,$AL3='King Node Model'!$AN$20,$AL3='King Node Model'!$AM$21,$AL3='King Node Model'!$AN$21,$AL3='King Node Model'!$AM$22,$AL3='King Node Model'!$AN$22),NOT(OR($AL3=$AN$5,$AL3=$AN$6,$AL3=$AN$7,$AL3=$AN$8,$AL3=$AN$10,$AL3=$AN$11))),NOT(AND(ISNUMBER('King Node Model'!$F$24),$AL3='King Node Model'!$F$24,IFERROR(INDEX('Level Engine'!$JN$9:$JN$55,MATCH($AL3,'Level Engine'!$AA$9:$AA$55,0)),0)<>1,$AL3<>'King Node Model'!$AL$49,$AL3<>'King Node Model'!$AL$50))),AND(AND(ISNUMBER($AL3),OR(AND($AL3>='King Node Model'!$AM$20,$AL3<='King Node Model'!$AN$20,$AS$23=1),$AL3='King Node Model'!$AM$20,$AL3='King Node Model'!$AN$20,$AL3='King Node Model'!$AM$21,$AL3='King Node Model'!$AN$21,$AL3='King Node Model'!$AM$22,$AL3='King Node Model'!$AN$22,$AL3='King Node Model'!$AL$49,$AL3='King Node Model'!$AL$50),OR($AL3=$AN$5,$AL3=$AN$6,$AL3=$AN$7,$AL3=$AN$8,$AL3=$AN$10,$AL3=$AN$11)),NOT(OR(AND('King Node Model'!$P$13="Up",OR($AL3=$AQ$22,$AL3=$AQ$23,$AL3=$AQ$24,$AL3='King Node Model'!$AM$20,$AL3='King Node Model'!$AM$21,$AL3='King Node Model'!$AM$22),OR(AND('King Node Model'!$B$23-$AL3>=0,'King Node Model'!$B$23-$AL3<=5),AND('King Node Model'!$C$23-$AL3>=0,'King Node Model'!$C$23-$AL3<=5))),AND('King Node Model'!$P$13="Down",OR($AL3=$AR$22,$AL3=$AR$23,$AL3=$AR$24,$AL3='King Node Model'!$AN$20,$AL3='King Node Model'!$AN$21,$AL3='King Node Model'!$AN$22),OR(AND($AL3-'King Node Model'!$B$23>=0,$AL3-'King Node Model'!$B$23<=5),AND($AL3-'King Node Model'!$C$24>=0,$AL3-'King Node Model'!$C$24<=5))))))),OR(COUNTIF('Level Engine'!$W$9:$W$14,$AL3)>0,COUNTIF('Level Engine'!$W$18:$W$23,$AL3)>0,$AL3='King Node Model'!$AL$42,$AL3='King Node Model'!$AL$43,$AL3='King Node Model'!$AL$44,$AL3='King Node Model'!$AL$49,$AL3='King Node Model'!$AL$50,$AL3='King Node Model'!$AL$51)),1,0)) -> 0 | AZ3: =IF($B$2="Hide unsafe",0,$BB3) -> 0 | BB3: =IF(OR(AND($AL3='King Node Model'!$AL$42,$AP$45<>"RASP"),AND($AL3='King Node Model'!$AL$43,$AP$46<>"RASP"),AND($AL3='King Node Model'!$AL$49,$AP$52<>"RASP"),AND($AL3='King Node Model'!$AL$50,$AP$53<>"RASP"),AND($AL3='King Node Model'!$AL$44,$AP$47<>"RASP"),AND($AL3='King Node Model'!$AL$51,$AP$54<>"RASP")),0,IF(AND(AND(ISNUMBER($AL3),OR(AND($AL3>=$AQ$22,$AL3<=$AR$22,$AP$45="RASP"),AND($AL3>=$AQ$23,$AL3<=$AR$23,$AP$46="RASP"),AND($AL3>=$AQ$24,$AL3<=$AR$24,$AP$47="RASP"),AND($AL3>='King Node Model'!$AM$20,$AL3<='King Node Model'!$AN$20,$AP$52="RASP",NOT($L$52=$AW$52)),AND($AL3='King Node Model'!$B$23,$AP$52="RASP",$L$52=$AW$52),AND($AL3>='King Node Model'!$AM$21,$AL3<='King Node Model'!$AN$21,$AP$53="RASP",NOT($L$53=$AW$53)),AND($AL3='King Node Model'!$B$23,$AP$53="RASP",$L$53=$AW$53),AND($AL3>='King Node Model'!$AM$22,$AL3<='King Node Model'!$AN$22,$AP$54="RASP"),AND($AL3>=IFERROR(INDEX('Level Engine'!$AT$9:$AT$55,MATCH('King Node Model'!$AL$42,'Level Engine'!$AA$9:$AA$55,0)),""),$AL3<=IFERROR(INDEX('Level Engine'!$AU$9:$AU$55,MATCH('King Node Model'!$AL$42,'Level Engine'!$AA$9:$AA$55,0)),""),$AP$45="RASP"),AND($AL3>=IFERROR(INDEX('Level Engine'!$AT$9:$AT$55,MATCH('King Node Model'!$AL$43,'Level Engine'!$AA$9:$AA$55,0)),""),$AL3<=IFERROR(INDEX('Level Engine'!$AU$9:$AU$55,MATCH('King Node Model'!$AL$43,'Level Engine'!$AA$9:$AA$55,0)),""),$AP$46="RASP"),AND($AL3>=IFERROR(INDEX('Level Engine'!$AT$9:$AT$55,MATCH('King Node Model'!$AL$44,'Level Engine'!$AA$9:$AA$55,0)),""),$AL3<=IFERROR(INDEX('Level Engine'!$AU$9:$AU$55,MATCH('King Node Model'!$AL$44,'Level Engine'!$AA$9:$AA$55,0)),""),$AP$47="RASP"),AND($AL3>=IFERROR(INDEX('Level Engine'!$AT$9:$AT$55,MATCH('King Node Model'!$AL$49,'Level Engine'!$AA$9:$AA$55,0)),""),$AL3<=IFERROR(INDEX('Level Engine'!$AU$9:$AU$55,MATCH('King Node Model'!$AL$49,'Level Engine'!$AA$9:$AA$55,0)),""),$AP$52="RASP",NOT($L$52=$AW$52)),AND($AL3>=IFERROR(INDEX('Level Engine'!$AT$9:$AT$55,MATCH('King Node Model'!$AL$50,'Level Engine'!$AA$9:$AA$55,0)),""),$AL3<=IFERROR(INDEX('Level Engine'!$AU$9:$AU$55,MATCH('King Node Model'!$AL$50,'Level Engine'!$AA$9:$AA$55,0)),""),$AP$53="RASP",NOT($L$53=$AW$53)),AND($AL3>=IFERROR(INDEX('Level Engine'!$AT$9:$AT$55,MATCH('King Node Model'!$AL$51,'Level Engine'!$AA$9:$AA$55,0)),""),$AL3<=IFERROR(INDEX('Level Engine'!$AU$9:$AU$55,MATCH('King Node Model'!$AL$51,'Level Engine'!$AA$9:$AA$55,0)),""),$AP$54="RASP"))),NOT(AND(ISNUMBER('King Node Model'!$F$24),$AL3='King Node Model'!$F$24,IFERROR(INDEX('Level Engine'!$JN$9:$JN$55,MATCH($AL3,'Level Engine'!$AA$9:$AA$55,0)),0)<>1,$AL3<>'King Node Model'!$AL$42,$AL3<>'King Node Model'!$AL$43,$AL3<>'King Node Model'!$AL$44,$AL3<>'King Node Model'!$AL$49,$AL3<>'King Node Model'!$AL$50,$AL3<>'King Node Model'!$AL$51))),1,0)) -> 0 | CO3: =IF(NOT(ISNUMBER($AL3)),"",IF(NOT(ISNUMBER(IFERROR(INDEX('Level Engine'!$FT$9:$FT$55,MATCH($AL3,'Level Engine'!$AA$9:$AA$55,0)),""))),"",IF(IFERROR(INDEX('Level Engine'!$FT$9:$FT$55,MATCH($AL3,'Level Engine'!$AA$9:$AA$55,0)),"")<0,0,2)+IF(ABS(IFERROR(INDEX('Level Engine'!$FT$9:$FT$55,MATCH($AL3,'Level Engine'!$AA$9:$AA$55,0)),""))>='Level Engine'!$FT$2,2,1))) -> 4 | DJ3: =IF(ISNUMBER($AL3),IF($AL3='Level Engine'!$BG$122," ⫪","")&IF($AL3='Level Engine'!$BG$118," S↑"&IFERROR(INDEX('Level Engine'!$MV$9:$MV$55,MATCH($AL3,'Level Engine'!$AA$9:$AA$55,0)),""),"")&IF($AL3='Level Engine'!$BG$119," S↓"&IFERROR(INDEX('Level Engine'!$MV$9:$MV$55,MATCH($AL3,'Level Engine'!$AA$9:$AA$55,0)),""),"")&IF($AL3='Level Engine'!$BG$120," D↑","")&IF($AL3='Level Engine'!$BG$121," D↓","")&IFERROR(INDEX('Level Engine'!$LG$9:$LG$55,MATCH($AL3,'Level Engine'!$AA$9:$AA$55,0)),"")&IF(IFERROR(INDEX('Level Engine'!$MA$9:$MA$55,MATCH($AL3,'Level Engine'!$AA$9:$AA$55,0)),0)=1," SAND","")&IF(IFERROR(INDEX('Level Engine'!$LM$9:$LM$55,MATCH($AL3,'Level Engine'!$AA$9:$AA$55,0)),0)>0," TP","")&IFERROR(" r"&MATCH($AL3,'Level Engine'!$W$9:$W$14,0),IFERROR(" s"&MATCH($AL3,'Level Engine'!$W$18:$W$23,0),""))&IF($AL3='Level Engine'!$BG$165," ◇","")&IF(N($DZ3)=1,IF($AL3>'Level Engine'!$BG$165," ⚠ DOM↓"," ⚠ DOM↑")&'Level Engine'!$BG$165,""),"") | DK3: =IF(AND(ISNUMBER($AL3),OR($AL3='King Node Model'!$AL$42,$AL3='King Node Model'!$AL$43,$AL3='King Node Model'!$AL$44)),IFERROR(MATCH($AL3,'Level Engine'!$W$9:$W$14,0),""),"") | DL3: =IF(AND(ISNUMBER($AL3),OR($AL3='King Node Model'!$AL$49,$AL3='King Node Model'!$AL$50,$AL3='King Node Model'!$AL$51)),IFERROR(MATCH($AL3,'Level Engine'!$W$18:$W$23,0),""),"") | DM3: =IF(AND(ISNUMBER($AL3),IFERROR(INDEX('Level Engine'!$LC$9:$LC$55,MATCH($AL3,'Level Engine'!$AA$9:$AA$55,0)),0)=1,OR($AL3=$AN$3,IFERROR(INDEX('Level Engine'!$LB$9:$LB$55,MATCH($AL3,'Level Engine'!$AA$9:$AA$55,0)),0)=1)),1,0) -> 0 | DZ3: =IF(ISNUMBER($AL3),IF(IFERROR(INDEX('Level Engine'!$NJ$9:$NJ$55,MATCH($AL3,'Level Engine'!$AA$9:$AA$55,0)),0)=1,1,0),0)
A4: =IF(AND(ISNUMBER($AM4),$AM4<0,ISNUMBER($AO4),$AO$1>0),REPT("█",ROUND($AO4/$AO$1*26,0)),"") | B4: =TEXT(IF(IF('Level Engine'!$GJ$4=1,$AL4='Level Engine'!$GJ$3,AND($AL4-$AM$2>-2.5,$AL4-$AM$2<=2.5)),$AM$2,$AL4),"0")&IF($AL4=$AN$1," ★","")&IF($AL4=$AN$2," ★","")&IF($AL4=$AN$3," ◆","")&IF(AND(ISNUMBER($AN$4),$AL4=$AN$4)," Ⓕ","")&IF(OR(AND(ISNUMBER('Level Engine'!$BG$87),$AL4='Level Engine'!$BG$87),AND(ISNUMBER('Level Engine'!$BG$105),$AL4='Level Engine'!$BG$105))," ζ","")&IF(AND(ISNUMBER($AN$35),$AL4=$AN$35)," ⓏⒼ","")&IF(OR($AL4='Level Engine'!$CP$4,$AL4='Level Engine'!$CP$5,$AL4='Level Engine'!$CP$6,$AL4='Level Engine'!$CP$7)," ☄","")&IF(OR($AL4=$AN$5,$AL4=$AN$8)," ║1","")&IF(OR($AL4=$AN$6,$AL4=$AN$10)," ║2","")&IF(OR($AL4=$AN$7,$AL4=$AN$11)," ║3","")&IF(OR($AL4=$AN$13,$AL4=$AN$16)," ▣1","")&IF(OR($AL4=$AN$14,$AL4=$AN$17)," ▣2","")&IF(OR($AL4=$AN$15,$AL4=$AN$18)," ▣3","")&IF(AND(NOT(OR(AND(ISNUMBER(SEARCH("chop edge",$E$45)),IFERROR(ABS($AL4-'King Node Model'!$AL$42)<=5,FALSE),NOT(ISNUMBER(SEARCH("UNSAFE",$L$45)))),AND(ISNUMBER(SEARCH("chop edge",$E$46)),IFERROR(ABS($AL4-'King Node Model'!$AL$43)<=5,FALSE),NOT(ISNUMBER(SEARCH("UNSAFE",$L$46)))),AND(ISNUMBER(SEARCH("chop edge",$E$52)),IFERROR(ABS($AL4-'King Node Model'!$AL$49)<=5,FALSE),NOT(ISNUMBER(SEARCH("UNSAFE",$L$52)))),AND(ISNUMBER(SEARCH("chop edge",$E$53)),IFERROR(ABS($AL4-'King Node Model'!$AL$50)<=5,FALSE),NOT(ISNUMBER(SEARCH("UNSAFE",$L$53)))))),OR(AND(IFERROR(INDEX('Level Engine'!$IB$9:$IB$55,MATCH('King Node Model'!$AL$49,'Level Engine'!$AA$9:$AA$55,0)),0)<>1,$AL4=IFERROR(INDEX('Level Engine'!$AU$9:$AU$55,MATCH('King Node Model'!$AL$49,'Level Engine'!$AA$9:$AA$55,0)),""),IFERROR(INDEX('Level Engine'!$AU$9:$AU$55,MATCH('King Node Model'!$AL$49,'Level Engine'!$AA$9:$AA$55,0)),"")<>IFERROR(INDEX('Level Engine'!$AT$9:$AT$55,MATCH('King Node Model'!$AL$49,'Level Engine'!$AA$9:$AA$55,0)),"")),AND(IFERROR(INDEX('Level Engine'!$IB$9:$IB$55,MATCH('King Node Model'!$AL$50,'Level Engine'!$AA$9:$AA$55,0)),0)<>1,$AL4=IFERROR(INDEX('Level Engine'!$AU$9:$AU$55,MATCH('King Node Model'!$AL$50,'Level Engine'!$AA$9:$AA$55,0)),""),IFERROR(INDEX('Level Engine'!$AU$9:$AU$55,MATCH('King Node Model'!$AL$50,'Level Engine'!$AA$9:$AA$55,0)),"")<>IFERROR(INDEX('Level Engine'!$AT$9:$AT$55,MATCH('King Node Model'!$AL$50,'Level Engine'!$AA$9:$AA$55,0)),"")))),IF(OR('King Node Model'!$A$8="Neg",N('Level Engine'!$BG$72)=1),""," ⒷⒽ"),"")&IF(AND(NOT(OR(AND(ISNUMBER(SEARCH("chop edge",$E$45)),IFERROR(ABS($AL4-'King Node Model'!$AL$42)<=5,FALSE),NOT(ISNUMBER(SEARCH("UNSAFE",$L$45)))),AND(ISNUMBER(SEARCH("chop edge",$E$46)),IFERROR(ABS($AL4-'King Node Model'!$AL$43)<=5,FALSE),NOT(ISNUMBER(SEARCH("UNSAFE",$L$46)))),AND(ISNUMBER(SEARCH("chop edge",$E$52)),IFERROR(ABS($AL4-'King Node Model'!$AL$49)<=5,FALSE),NOT(ISNUMBER(SEARCH("UNSAFE",$L$52)))),AND(ISNUMBER(SEARCH("chop edge",$E$53)),IFERROR(ABS($AL4-'King Node Model'!$AL$50)<=5,FALSE),NOT(ISNUMBER(SEARCH("UNSAFE",$L$53)))))),OR(AND(IFERROR(INDEX('Level Engine'!$IB$9:$IB$55,MATCH('King Node Model'!$AL$42,'Level Engine'!$AA$9:$AA$55,0)),0)<>1,$AL4=IFERROR(INDEX('Level Engine'!$AT$9:$AT$55,MATCH('King Node Model'!$AL$42,'Level Engine'!$AA$9:$AA$55,0)),""),IFERROR(INDEX('Level Engine'!$AT$9:$AT$55,MATCH('King Node Model'!$AL$42,'Level Engine'!$AA$9:$AA$55,0)),"")<>IFERROR(INDEX('Level Engine'!$AU$9:$AU$55,MATCH('King Node Model'!$AL$42,'Level Engine'!$AA$9:$AA$55,0)),"")),AND(IFERROR(INDEX('Level Engine'!$IB$9:$IB$55,MATCH('King Node Model'!$AL$43,'Level Engine'!$AA$9:$AA$55,0)),0)<>1,$AL4=IFERROR(INDEX('Level Engine'!$AT$9:$AT$55,MATCH('King Node Model'!$AL$43,'Level Engine'!$AA$9:$AA$55,0)),""),IFERROR(INDEX('Level Engine'!$AT$9:$AT$55,MATCH('King Node Model'!$AL$43,'Level Engine'!$AA$9:$AA$55,0)),"")<>IFERROR(INDEX('Level Engine'!$AU$9:$AU$55,MATCH('King Node Model'!$AL$43,'Level Engine'!$AA$9:$AA$55,0)),"")))),IF(OR('King Node Model'!$A$8="Neg",N('Level Engine'!$BG$72)=1),""," ⒷⓁ"),"")&IF(OR(AND($AL4>='King Node Model'!$AM$17,$AL4<='King Node Model'!$AN$17,$AP$45="RASP"),AND($AL4>='King Node Model'!$AM$18,$AL4<='King Node Model'!$AN$18,$AP$46="RASP"),AND($AL4>='King Node Model'!$AM$19,$AL4<='King Node Model'!$AN$19,$AP$47="RASP"),AND($AL4>='King Node Model'!$AM$20,$AL4<='King Node Model'!$AN$20,$AP$52="RASP"),AND($AL4>='King Node Model'!$AM$21,$AL4<='King Node Model'!$AN$21,$AP$53="RASP"),AND($AL4>='King Node Model'!$AM$22,$AL4<='King Node Model'!$AN$22,$AP$54="RASP")),"","")&IF(IF('Level Engine'!$GJ$4=1,$AL4='Level Engine'!$GJ$3,AND($AL4-$AM$2>-2.5,$AL4-$AM$2<=2.5))," ◄","")&IF(IFERROR(INDEX('Level Engine'!$GV$9:$GV$55,MATCH($AL4,'Level Engine'!$AA$9:$AA$55,0)),0)=1," Ⓥ"&IF(IFERROR(INDEX('Level Engine'!$ET$9:$ET$55,MATCH($AL4,'Level Engine'!$AA$9:$AA$55,0)),0)=1,"+",""),"")&IF(OR(AND($AL4=$AN$38,IFERROR(INDEX('Level Engine'!$AN$9:$AN$55,MATCH($AL4,'Level Engine'!$AA$9:$AA$55,0)),0)<>1),$AL4=$AN$39)," ⊙","")&IF(AND(OR('King Node Model'!$A$8="Neg",N('Level Engine'!$BG$72)=1),ABS(MIN($AM$3:$AM$64))>MAX($AM$3:$AM$64),$AN$2<$AM$2,$AL4<$AM$2,ABS($AL4-$AN$2)<=5,IFERROR(VALUE(MID('King Node Model'!$K$26,FIND(":",'King Node Model'!$K$26)-2,2)),0)>=19,IFERROR(INDEX('Level Engine'!$EJ$9:$EJ$55,MATCH($AL4,'Level Engine'!$AA$9:$AA$55,0)),0)=0,$AN$3>$AM$2)," ⟲rev","")&IF($AL4='King Node Model'!$F$24," ⟂","")&$DJ4&IF(IFERROR(INDEX('Level Engine'!$EN$9:$EN$55,MATCH($AL4,'Level Engine'!$AA$9:$AA$55,0)),0)=1," Ⓟ"&IF(AND(OR('King Node Model'!$A$8="Neg",N('Level Engine'!$BG$72)=1),IFERROR(INDEX('Level Engine'!$AN$9:$AN$55,MATCH($AL4,'Level Engine'!$AA$9:$AA$55,0)),0)<>1)," NO-REV",""),"")&IF(AND(ISNUMBER($AL4),OR(AND(ISNUMBER(SEARCH("chop edge",$E$45)),$AL4='King Node Model'!$AL$42),AND(ISNUMBER(SEARCH("chop edge",$E$46)),$AL4='King Node Model'!$AL$43),AND(ISNUMBER(SEARCH("chop edge",$E$52)),$AL4='King Node Model'!$AL$49),AND(ISNUMBER(SEARCH("chop edge",$E$53)),$AL4='King Node Model'!$AL$50)))," ⒸⒺ","")&IF(AND('Level Engine'!$GJ$4=1,OR($AL4='Level Engine'!$GJ$1,$AL4='Level Engine'!$GJ$2)),"","")&IF(ABS(N(IFERROR(INDEX('Level Engine'!$AE$9:$AE$55,MATCH($AL4,'Level Engine'!$AA$9:$AA$55,0)),0)))>='Level Engine'!$BG$85,IF(N(IFERROR(INDEX('Level Engine'!$AE$9:$AE$55,MATCH($AL4,'Level Engine'!$AA$9:$AA$55,0)),0))>0," Δ+"," Δ−"),"")&IFERROR(IF(AND(ISNUMBER(MATCH($AL4,'Level Engine'!$AA$9:$AA$55,0)),ABS(N(IFERROR(INDEX('Level Engine'!$AE$9:$AE$55,MATCH($AL4,'Level Engine'!$AA$9:$AA$55,0)),0)))<'Level Engine'!$BG$85,ABS(N(IFERROR(INDEX('Level Engine'!$AE$9:$AE$55,MATCH($AL4,'Level Engine'!$AA$9:$AA$55,0)),0)))<=ABS(N(IFERROR(INDEX('Level Engine'!$AE$9:$AE$55,MATCH($AL4+5,'Level Engine'!$AA$9:$AA$55,0)),0))),ABS(N(IFERROR(INDEX('Level Engine'!$AE$9:$AE$55,MATCH($AL4,'Level Engine'!$AA$9:$AA$55,0)),0)))<=ABS(N(IFERROR(INDEX('Level Engine'!$AE$9:$AE$55,MATCH($AL4-5,'Level Engine'!$AA$9:$AA$55,0)),0))),OR(AND(ABS(N(IFERROR(INDEX('Level Engine'!$AE$9:$AE$55,MATCH($AL4+5,'Level Engine'!$AA$9:$AA$55,0)),0)))>='Level Engine'!$BG$85,ABS(N(IFERROR(INDEX('Level Engine'!$AE$9:$AE$55,MATCH($AL4,'Level Engine'!$AA$9:$AA$55,0)),0)))<='Level Engine'!$BG$88*ABS(N(IFERROR(INDEX('Level Engine'!$AE$9:$AE$55,MATCH($AL4+5,'Level Engine'!$AA$9:$AA$55,0)),0)))),AND(ABS(N(IFERROR(INDEX('Level Engine'!$AE$9:$AE$55,MATCH($AL4-5,'Level Engine'!$AA$9:$AA$55,0)),0)))>='Level Engine'!$BG$85,ABS(N(IFERROR(INDEX('Level Engine'!$AE$9:$AE$55,MATCH($AL4,'Level Engine'!$AA$9:$AA$55,0)),0)))<='Level Engine'!$BG$88*ABS(N(IFERROR(INDEX('Level Engine'!$AE$9:$AE$55,MATCH($AL4-5,'Level Engine'!$AA$9:$AA$55,0)),0)))))),IF(AND('King Node Model'!$A$8="Pos",N('Level Engine'!$BG$72)<>1),""," ∅"),""),"")&IF(IFERROR(INDEX('Level Engine'!$JD$9:$JD$55,MATCH($AL4,'Level Engine'!$AA$9:$AA$55,0)),"")="P"," P-OI",IF(IFERROR(INDEX('Level Engine'!$JD$9:$JD$55,MATCH($AL4,'Level Engine'!$AA$9:$AA$55,0)),"")="C"," C-OI","")) -> 7880 C-OI | C4: =IF(AND(ISNUMBER($AM4),$AM4>0,ISNUMBER($AO4),$AO$1>0),REPT("█",ROUND($AO4/$AO$1*26,0)),"") | D4: =IF(NOT(ISNUMBER($AL4)),"",IF(IFERROR(INDEX('Level Engine'!$FS$9:$FS$55,MATCH($AL4,'Level Engine'!$AA$9:$AA$55,0)),0)=1,"⊙","")) | E4: ="VIX "&TEXT('King Node Model'!$B$5,"0.0") -> VIX 15.4 | G4: ="VVIX "&TEXT('King Node Model'!$D$5,"0.0") -> VVIX 86.6 | I4: ="VIX1D "&TEXT('King Node Model'!$F$5,"0.0") -> VIX1D 8.5 | Q4: Level | R4: Direction | S4: ATM IV | AL4: ='King Node Model'!A30 -> 7880 | AM4: ='King Node Model'!C30 -> 75905 | AN4: ='King Node Model'!D26 -> 7805 | AO4: ='King Node Model'!B30 -> 76929 | AY4: =IF(AND($B$2="Hide unsafe",$BB4=1),0,IF(AND(OR(AND(AND(ISNUMBER($AL4),OR(AND($AL4>=$AQ$22,$AL4<=$AR$22,$AS$22=1),$AL4=$AQ$22,$AL4=$AR$22,$AL4=$AQ$23,$AL4=$AR$23,$AL4=$AQ$24,$AL4=$AR$24),NOT(OR($AL4=$AN$5,$AL4=$AN$6,$AL4=$AN$7,$AL4=$AN$8,$AL4=$AN$10,$AL4=$AN$11))),NOT(OR(AND('King Node Model'!$P$13="Up",OR($AL4=$AQ$22,$AL4=$AQ$23,$AL4=$AQ$24,$AL4='King Node Model'!$AM$20,$AL4='King Node Model'!$AM$21,$AL4='King Node Model'!$AM$22),OR(AND('King Node Model'!$B$23-$AL4>=0,'King Node Model'!$B$23-$AL4<=5),AND('King Node Model'!$C$23-$AL4>=0,'King Node Model'!$C$23-$AL4<=5))),AND('King Node Model'!$P$13="Down",OR($AL4=$AR$22,$AL4=$AR$23,$AL4=$AR$24,$AL4='King Node Model'!$AN$20,$AL4='King Node Model'!$AN$21,$AL4='King Node Model'!$AN$22),OR(AND($AL4-'King Node Model'!$B$23>=0,$AL4-'King Node Model'!$B$23<=5),AND($AL4-'King Node Model'!$C$24>=0,$AL4-'King Node Model'!$C$24<=5)))))),AND(AND(ISNUMBER($AL4),OR(AND($AL4>=$AQ$22,$AL4<=$AR$22,$AS$22=1),$AL4=$AQ$22,$AL4=$AR$22,$AL4=$AQ$23,$AL4=$AR$23,$AL4=$AQ$24,$AL4=$AR$24,$AL4='King Node Model'!$AL$42,$AL4='King Node Model'!$AL$43),OR($AL4=$AN$5,$AL4=$AN$6,$AL4=$AN$7,$AL4=$AN$8,$AL4=$AN$10,$AL4=$AN$11)),NOT(OR(AND('King Node Model'!$P$13="Up",OR($AL4=$AQ$22,$AL4=$AQ$23,$AL4=$AQ$24,$AL4='King Node Model'!$AM$20,$AL4='King Node Model'!$AM$21,$AL4='King Node Model'!$AM$22),OR(AND('King Node Model'!$B$23-$AL4>=0,'King Node Model'!$B$23-$AL4<=5),AND('King Node Model'!$C$23-$AL4>=0,'King Node Model'!$C$23-$AL4<=5))),AND('King Node Model'!$P$13="Down",OR($AL4=$AR$22,$AL4=$AR$23,$AL4=$AR$24,$AL4='King Node Model'!$AN$20,$AL4='King Node Model'!$AN$21,$AL4='King Node Model'!$AN$22),OR(AND($AL4-'King Node Model'!$B$23>=0,$AL4-'King Node Model'!$B$23<=5),AND($AL4-'King Node Model'!$C$24>=0,$AL4-'King Node Model'!$C$24<=5)))))),AND(AND(ISNUMBER($AL4),OR(AND($AL4>='King Node Model'!$AM$20,$AL4<='King Node Model'!$AN$20,$AS$23=1),$AL4='King Node Model'!$AM$20,$AL4='King Node Model'!$AN$20,$AL4='King Node Model'!$AM$21,$AL4='King Node Model'!$AN$21,$AL4='King Node Model'!$AM$22,$AL4='King Node Model'!$AN$22),NOT(OR($AL4=$AN$5,$AL4=$AN$6,$AL4=$AN$7,$AL4=$AN$8,$AL4=$AN$10,$AL4=$AN$11))),NOT(AND(ISNUMBER('King Node Model'!$F$24),$AL4='King Node Model'!$F$24,IFERROR(INDEX('Level Engine'!$JN$9:$JN$55,MATCH($AL4,'Level Engine'!$AA$9:$AA$55,0)),0)<>1))),AND(AND(ISNUMBER($AL4),OR(AND($AL4>='King Node Model'!$AM$20,$AL4<='King Node Model'!$AN$20,$AS$23=1),$AL4='King Node Model'!$AM$20,$AL4='King Node Model'!$AN$20,$AL4='King Node Model'!$AM$21,$AL4='King Node Model'!$AN$21,$AL4='King Node Model'!$AM$22,$AL4='King Node Model'!$AN$22,$AL4='King Node Model'!$AL$49,$AL4='King Node Model'!$AL$50),OR($AL4=$AN$5,$AL4=$AN$6,$AL4=$AN$7,$AL4=$AN$8,$AL4=$AN$10,$AL4=$AN$11)),NOT(OR(AND('King Node Model'!$P$13="Up",OR($AL4=$AQ$22,$AL4=$AQ$23,$AL4=$AQ$24,$AL4='King Node Model'!$AM$20,$AL4='King Node Model'!$AM$21,$AL4='King Node Model'!$AM$22),OR(AND('King Node Model'!$B$23-$AL4>=0,'King Node Model'!$B$23-$AL4<=5),AND('King Node Model'!$C$23-$AL4>=0,'King Node Model'!$C$23-$AL4<=5))),AND('King Node Model'!$P$13="Down",OR($AL4=$AR$22,$AL4=$AR$23,$AL4=$AR$24,$AL4='King Node Model'!$AN$20,$AL4='King Node Model'!$AN$21,$AL4='King Node Model'!$AN$22),OR(AND($AL4-'King Node Model'!$B$23>=0,$AL4-'King Node Model'!$B$23<=5),AND($AL4-'King Node Model'!$C$24>=0,$AL4-'King Node Model'!$C$24<=5))))))),OR(COUNTIF('Level Engine'!$W$9:$W$14,$AL4)>0,COUNTIF('Level Engine'!$W$18:$W$23,$AL4)>0)),1,0)) -> 0 | AZ4: =IF($B$2="Hide unsafe",0,$BB4) -> 0 | BB4: =IF(OR(AND($AL4='King Node Model'!$AL$42,$AP$45<>"RASP"),AND($AL4='King Node Model'!$AL$43,$AP$46<>"RASP"),AND($AL4='King Node Model'!$AL$49,$AP$52<>"RASP"),AND($AL4='King Node Model'!$AL$50,$AP$53<>"RASP"),AND($AL4='King Node Model'!$AL$44,$AP$47<>"RASP"),AND($AL4='King Node Model'!$AL$51,$AP$54<>"RASP")),0,IF(AND(AND(ISNUMBER($AL4),OR(AND($AL4>=$AQ$22,$AL4<=$AR$22,$AP$45="RASP"),AND($AL4>=$AQ$23,$AL4<=$AR$23,$AP$46="RASP"),AND($AL4>=$AQ$24,$AL4<=$AR$24,$AP$47="RASP"),AND($AL4>='King Node Model'!$AM$20,$AL4<='King Node Model'!$AN$20,$AP$52="RASP",NOT($L$52=$AW$52)),AND($AL4='King Node Model'!$B$23,$AP$52="RASP",$L$52=$AW$52),AND($AL4>='King Node Model'!$AM$21,$AL4<='King Node Model'!$AN$21,$AP$53="RASP",NOT($L$53=$AW$53)),AND($AL4='King Node Model'!$B$23,$AP$53="RASP",$L$53=$AW$53),AND($AL4>='King Node Model'!$AM$22,$AL4<='King Node Model'!$AN$22,$AP$54="RASP"),AND($AL4>=IFERROR(INDEX('Level Engine'!$AT$9:$AT$55,MATCH('King Node Model'!$AL$42,'Level Engine'!$AA$9:$AA$55,0)),""),$AL4<=IFERROR(INDEX('Level Engine'!$AU$9:$AU$55,MATCH('King Node Model'!$AL$42,'Level Engine'!$AA$9:$AA$55,0)),""),$AP$45="RASP"),AND($AL4>=IFERROR(INDEX('Level Engine'!$AT$9:$AT$55,MATCH('King Node Model'!$AL$43,'Level Engine'!$AA$9:$AA$55,0)),""),$AL4<=IFERROR(INDEX('Level Engine'!$AU$9:$AU$55,MATCH('King Node Model'!$AL$43,'Level Engine'!$AA$9:$AA$55,0)),""),$AP$46="RASP"),AND($AL4>=IFERROR(INDEX('Level Engine'!$AT$9:$AT$55,MATCH('King Node Model'!$AL$44,'Level Engine'!$AA$9:$AA$55,0)),""),$AL4<=IFERROR(INDEX('Level Engine'!$AU$9:$AU$55,MATCH('King Node Model'!$AL$44,'Level Engine'!$AA$9:$AA$55,0)),""),$AP$47="RASP"),AND($AL4>=IFERROR(INDEX('Level Engine'!$AT$9:$AT$55,MATCH('King Node Model'!$AL$49,'Level Engine'!$AA$9:$AA$55,0)),""),$AL4<=IFERROR(INDEX('Level Engine'!$AU$9:$AU$55,MATCH('King Node Model'!$AL$49,'Level Engine'!$AA$9:$AA$55,0)),""),$AP$52="RASP",NOT($L$52=$AW$52)),AND($AL4>=IFERROR(INDEX('Level Engine'!$AT$9:$AT$55,MATCH('King Node Model'!$AL$50,'Level Engine'!$AA$9:$AA$55,0)),""),$AL4<=IFERROR(INDEX('Level Engine'!$AU$9:$AU$55,MATCH('King Node Model'!$AL$50,'Level Engine'!$AA$9:$AA$55,0)),""),$AP$53="RASP",NOT($L$53=$AW$53)),AND($AL4>=IFERROR(INDEX('Level Engine'!$AT$9:$AT$55,MATCH('King Node Model'!$AL$51,'Level Engine'!$AA$9:$AA$55,0)),""),$AL4<=IFERROR(INDEX('Level Engine'!$AU$9:$AU$55,MATCH('King Node Model'!$AL$51,'Level Engine'!$AA$9:$AA$55,0)),""),$AP$54="RASP"))),NOT(AND(ISNUMBER('King Node Model'!$F$24),$AL4='King Node Model'!$F$24,IFERROR(INDEX('Level Engine'!$JN$9:$JN$55,MATCH($AL4,'Level Engine'!$AA$9:$AA$55,0)),0)<>1,$AL4<>'King Node Model'!$AL$42,$AL4<>'King Node Model'!$AL$43,$AL4<>'King Node Model'!$AL$44,$AL4<>'King Node Model'!$AL$49,$AL4<>'King Node Model'!$AL$50,$AL4<>'King Node Model'!$AL$51))),1,0)) -> 0 | CO4: =IF(NOT(ISNUMBER($AL4)),"",IF(NOT(ISNUMBER(IFERROR(INDEX('Level Engine'!$FT$9:$FT$55,MATCH($AL4,'Level Engine'!$AA$9:$AA$55,0)),""))),"",IF(IFERROR(INDEX('Level Engine'!$FT$9:$FT$55,MATCH($AL4,'Level Engine'!$AA$9:$AA$55,0)),"")<0,0,2)+IF(ABS(IFERROR(INDEX('Level Engine'!$FT$9:$FT$55,MATCH($AL4,'Level Engine'!$AA$9:$AA$55,0)),""))>='Level Engine'!$FT$2,2,1))) -> 4 | DJ4: =IF(ISNUMBER($AL4),IF($AL4='Level Engine'!$BG$122," ⫪","")&IF($AL4='Level Engine'!$BG$118," S↑"&IFERROR(INDEX('Level Engine'!$MV$9:$MV$55,MATCH($AL4,'Level Engine'!$AA$9:$AA$55,0)),""),"")&IF($AL4='Level Engine'!$BG$119," S↓"&IFERROR(INDEX('Level Engine'!$MV$9:$MV$55,MATCH($AL4,'Level Engine'!$AA$9:$AA$55,0)),""),"")&IF($AL4='Level Engine'!$BG$120," D↑","")&IF($AL4='Level Engine'!$BG$121," D↓","")&IFERROR(INDEX('Level Engine'!$LG$9:$LG$55,MATCH($AL4,'Level Engine'!$AA$9:$AA$55,0)),"")&IF(IFERROR(INDEX('Level Engine'!$MA$9:$MA$55,MATCH($AL4,'Level Engine'!$AA$9:$AA$55,0)),0)=1," SAND","")&IF(IFERROR(INDEX('Level Engine'!$LM$9:$LM$55,MATCH($AL4,'Level Engine'!$AA$9:$AA$55,0)),0)>0," TP","")&IFERROR(" r"&MATCH($AL4,'Level Engine'!$W$9:$W$14,0),IFERROR(" s"&MATCH($AL4,'Level Engine'!$W$18:$W$23,0),""))&IF($AL4='Level Engine'!$BG$165," ◇","")&IF(N($DZ4)=1,IF($AL4>'Level Engine'!$BG$165," ⚠ DOM↓"," ⚠ DOM↑")&'Level Engine'!$BG$165,""),"") | DK4: =IF(AND(ISNUMBER($AL4),OR($AL4='King Node Model'!$AL$42,$AL4='King Node Model'!$AL$43,$AL4='King Node Model'!$AL$44)),IFERROR(MATCH($AL4,'Level Engine'!$W$9:$W$14,0),""),"") | DL4: =IF(AND(ISNUMBER($AL4),OR($AL4='King Node Model'!$AL$49,$AL4='King Node Model'!$AL$50,$AL4='King Node Model'!$AL$51)),IFERROR(MATCH($AL4,'Level Engine'!$W$18:$W$23,0),""),"") | DM4: =IF(AND(ISNUMBER($AL4),IFERROR(INDEX('Level Engine'!$LC$9:$LC$55,MATCH($AL4,'Level Engine'!$AA$9:$AA$55,0)),0)=1,OR($AL4=$AN$3,IFERROR(INDEX('Level Engine'!$LB$9:$LB$55,MATCH($AL4,'Level Engine'!$AA$9:$AA$55,0)),0)=1)),1,0) -> 0 | DZ4: =IF(ISNUMBER($AL4),IF(IFERROR(INDEX('Level Engine'!$NJ$9:$NJ$55,MATCH($AL4,'Level Engine'!$AA$9:$AA$55,0)),0)=1,1,0),0)
B5: =TEXT(IF(IF('Level Engine'!$GJ$4=1,$AL5='Level Engine'!$GJ$3,AND($AL5-$AM$2>-2.5,$AL5-$AM$2<=2.5)),$AM$2,$AL5),"0")&IF($AL5=$AN$1," ★","")&IF($AL5=$AN$2," ★","")&IF($AL5=$AN$3," ◆","")&IF(AND(ISNUMBER($AN$4),$AL5=$AN$4)," Ⓕ","")&IF(OR(AND(ISNUMBER('Level Engine'!$BG$87),$AL5='Level Engine'!$BG$87),AND(ISNUMBER('Level Engine'!$BG$105),$AL5='Level Engine'!$BG$105))," ζ","")&IF(AND(ISNUMBER($AN$35),$AL5=$AN$35)," ⓏⒼ","")&IF(OR($AL5='Level Engine'!$CP$4,$AL5='Level Engine'!$CP$5,$AL5='Level Engine'!$CP$6,$AL5='Level Engine'!$CP$7)," ☄","")&IF(OR($AL5=$AN$5,$AL5=$AN$8)," ║1","")&IF(OR($AL5=$AN$6,$AL5=$AN$10)," ║2","")&IF(OR($AL5=$AN$7,$AL5=$AN$11)," ║3","")&IF(OR($AL5=$AN$13,$AL5=$AN$16)," ▣1","")&IF(OR($AL5=$AN$14,$AL5=$AN$17)," ▣2","")&IF(OR($AL5=$AN$15,$AL5=$AN$18)," ▣3","")&IF(AND(NOT(OR(AND(ISNUMBER(SEARCH("chop edge",$E$45)),IFERROR(ABS($AL5-'King Node Model'!$AL$42)<=5,FALSE),NOT(ISNUMBER(SEARCH("UNSAFE",$L$45)))),AND(ISNUMBER(SEARCH("chop edge",$E$46)),IFERROR(ABS($AL5-'King Node Model'!$AL$43)<=5,FALSE),NOT(ISNUMBER(SEARCH("UNSAFE",$L$46)))),AND(ISNUMBER(SEARCH("chop edge",$E$52)),IFERROR(ABS($AL5-'King Node Model'!$AL$49)<=5,FALSE),NOT(ISNUMBER(SEARCH("UNSAFE",$L$52)))),AND(ISNUMBER(SEARCH("chop edge",$E$53)),IFERROR(ABS($AL5-'King Node Model'!$AL$50)<=5,FALSE),NOT(ISNUMBER(SEARCH("UNSAFE",$L$53)))))),OR(AND(IFERROR(INDEX('Level Engine'!$IB$9:$IB$55,MATCH('King Node Model'!$AL$49,'Level Engine'!$AA$9:$AA$55,0)),0)<>1,$AL5=IFERROR(INDEX('Level Engine'!$AU$9:$AU$55,MATCH('King Node Model'!$AL$49,'Level Engine'!$AA$9:$AA$55,0)),""),IFERROR(INDEX('Level Engine'!$AU$9:$AU$55,MATCH('King Node Model'!$AL$49,'Level Engine'!$AA$9:$AA$55,0)),"")<>IFERROR(INDEX('Level Engine'!$AT$9:$AT$55,MATCH('King Node Model'!$AL$49,'Level Engine'!$AA$9:$AA$55,0)),"")),AND(IFERROR(INDEX('Level Engine'!$IB$9:$IB$55,MATCH('King Node Model'!$AL$50,'Level Engine'!$AA$9:$AA$55,0)),0)<>1,$AL5=IFERROR(INDEX('Level Engine'!$AU$9:$AU$55,MATCH('King Node Model'!$AL$50,'Level Engine'!$AA$9:$AA$55,0)),""),IFERROR(INDEX('Level Engine'!$AU$9:$AU$55,MATCH('King Node Model'!$AL$50,'Level Engine'!$AA$9:$AA$55,0)),"")<>IFERROR(INDEX('Level Engine'!$AT$9:$AT$55,MATCH('King Node Model'!$AL$50,'Level Engine'!$AA$9:$AA$55,0)),"")))),IF(OR('King Node Model'!$A$8="Neg",N('Level Engine'!$BG$72)=1),""," ⒷⒽ"),"")&IF(AND(NOT(OR(AND(ISNUMBER(SEARCH("chop edge",$E$45)),IFERROR(ABS($AL5-'King Node Model'!$AL$42)<=5,FALSE),NOT(ISNUMBER(SEARCH("UNSAFE",$L$45)))),AND(ISNUMBER(SEARCH("chop edge",$E$46)),IFERROR(ABS($AL5-'King Node Model'!$AL$43)<=5,FALSE),NOT(ISNUMBER(SEARCH("UNSAFE",$L$46)))),AND(ISNUMBER(SEARCH("chop edge",$E$52)),IFERROR(ABS($AL5-'King Node Model'!$AL$49)<=5,FALSE),NOT(ISNUMBER(SEARCH("UNSAFE",$L$52)))),AND(ISNUMBER(SEARCH("chop edge",$E$53)),IFERROR(ABS($AL5-'King Node Model'!$AL$50)<=5,FALSE),NOT(ISNUMBER(SEARCH("UNSAFE",$L$53)))))),OR(AND(IFERROR(INDEX('Level Engine'!$IB$9:$IB$55,MATCH('King Node Model'!$AL$42,'Level Engine'!$AA$9:$AA$55,0)),0)<>1,$AL5=IFERROR(INDEX('Level Engine'!$AT$9:$AT$55,MATCH('King Node Model'!$AL$42,'Level Engine'!$AA$9:$AA$55,0)),""),IFERROR(INDEX('Level Engine'!$AT$9:$AT$55,MATCH('King Node Model'!$AL$42,'Level Engine'!$AA$9:$AA$55,0)),"")<>IFERROR(INDEX('Level Engine'!$AU$9:$AU$55,MATCH('King Node Model'!$AL$42,'Level Engine'!$AA$9:$AA$55,0)),"")),AND(IFERROR(INDEX('Level Engine'!$IB$9:$IB$55,MATCH('King Node Model'!$AL$43,'Level Engine'!$AA$9:$AA$55,0)),0)<>1,$AL5=IFERROR(INDEX('Level Engine'!$AT$9:$AT$55,MATCH('King Node Model'!$AL$43,'Level Engine'!$AA$9:$AA$55,0)),""),IFERROR(INDEX('Level Engine'!$AT$9:$AT$55,MATCH('King Node Model'!$AL$43,'Level Engine'!$AA$9:$AA$55,0)),"")<>IFERROR(INDEX('Level Engine'!$AU$9:$AU$55,MATCH('King Node Model'!$AL$43,'Level Engine'!$AA$9:$AA$55,0)),"")))),IF(OR('King Node Model'!$A$8="Neg",N('Level Engine'!$BG$72)=1),""," ⒷⓁ"),"")&IF(OR(AND($AL5>='King Node Model'!$AM$17,$AL5<='King Node Model'!$AN$17,$AP$45="RASP"),AND($AL5>='King Node Model'!$AM$18,$AL5<='King Node Model'!$AN$18,$AP$46="RASP"),AND($AL5>='King Node Model'!$AM$19,$AL5<='King Node Model'!$AN$19,$AP$47="RASP"),AND($AL5>='King Node Model'!$AM$20,$AL5<='King Node Model'!$AN$20,$AP$52="RASP"),AND($AL5>='King Node Model'!$AM$21,$AL5<='King Node Model'!$AN$21,$AP$53="RASP"),AND($AL5>='King Node Model'!$AM$22,$AL5<='King Node Model'!$AN$22,$AP$54="RASP")),"","")&IF(IF('Level Engine'!$GJ$4=1,$AL5='Level Engine'!$GJ$3,AND($AL5-$AM$2>-2.5,$AL5-$AM$2<=2.5))," ◄","")&IF(IFERROR(INDEX('Level Engine'!$GV$9:$GV$55,MATCH($AL5,'Level Engine'!$AA$9:$AA$55,0)),0)=1," Ⓥ"&IF(IFERROR(INDEX('Level Engine'!$ET$9:$ET$55,MATCH($AL5,'Level Engine'!$AA$9:$AA$55,0)),0)=1,"+",""),"")&IF(OR(AND($AL5=$AN$38,IFERROR(INDEX('Level Engine'!$AN$9:$AN$55,MATCH($AL5,'Level Engine'!$AA$9:$AA$55,0)),0)<>1),$AL5=$AN$39)," ⊙","")&IF(AND(OR('King Node Model'!$A$8="Neg",N('Level Engine'!$BG$72)=1),ABS(MIN($AM$3:$AM$64))>MAX($AM$3:$AM$64),$AN$2<$AM$2,$AL5<$AM$2,ABS($AL5-$AN$2)<=5,IFERROR(VALUE(MID('King Node Model'!$K$26,FIND(":",'King Node Model'!$K$26)-2,2)),0)>=19,IFERROR(INDEX('Level Engine'!$EJ$9:$EJ$55,MATCH($AL5,'Level Engine'!$AA$9:$AA$55,0)),0)=0,$AN$3>$AM$2)," ⟲rev","")&IF($AL5='King Node Model'!$F$24," ⟂","")&$DJ5&IF(IFERROR(INDEX('Level Engine'!$EN$9:$EN$55,MATCH($AL5,'Level Engine'!$AA$9:$AA$55,0)),0)=1," Ⓟ"&IF(AND(OR('King Node Model'!$A$8="Neg",N('Level Engine'!$BG$72)=1),IFERROR(INDEX('Level Engine'!$AN$9:$AN$55,MATCH($AL5,'Level Engine'!$AA$9:$AA$55,0)),0)<>1)," NO-REV",""),"")&IF(AND(ISNUMBER($AL5),OR(AND(ISNUMBER(SEARCH("chop edge",$E$45)),$AL5='King Node Model'!$AL$42),AND(ISNUMBER(SEARCH("chop edge",$E$46)),$AL5='King Node Model'!$AL$43),AND(ISNUMBER(SEARCH("chop edge",$E$52)),$AL5='King Node Model'!$AL$49),AND(ISNUMBER(SEARCH("chop edge",$E$53)),$AL5='King Node Model'!$AL$50)))," ⒸⒺ","")&IF(AND('Level Engine'!$GJ$4=1,OR($AL5='Level Engine'!$GJ$1,$AL5='Level Engine'!$GJ$2)),"","")&IF(ABS(N(IFERROR(INDEX('Level Engine'!$AE$9:$AE$55,MATCH($AL5,'Level Engine'!$AA$9:$AA$55,0)),0)))>='Level Engine'!$BG$85,IF(N(IFERROR(INDEX('Level Engine'!$AE$9:$AE$55,MATCH($AL5,'Level Engine'!$AA$9:$AA$55,0)),0))>0," Δ+"," Δ−"),"")&IFERROR(IF(AND(ISNUMBER(MATCH($AL5,'Level Engine'!$AA$9:$AA$55,0)),ABS(N(IFERROR(INDEX('Level Engine'!$AE$9:$AE$55,MATCH($AL5,'Level Engine'!$AA$9:$AA$55,0)),0)))<'Level Engine'!$BG$85,ABS(N(IFERROR(INDEX('Level Engine'!$AE$9:$AE$55,MATCH($AL5,'Level Engine'!$AA$9:$AA$55,0)),0)))<=ABS(N(IFERROR(INDEX('Level Engine'!$AE$9:$AE$55,MATCH($AL5+5,'Level Engine'!$AA$9:$AA$55,0)),0))),ABS(N(IFERROR(INDEX('Level Engine'!$AE$9:$AE$55,MATCH($AL5,'Level Engine'!$AA$9:$AA$55,0)),0)))<=ABS(N(IFERROR(INDEX('Level Engine'!$AE$9:$AE$55,MATCH($AL5-5,'Level Engine'!$AA$9:$AA$55,0)),0))),OR(AND(ABS(N(IFERROR(INDEX('Level Engine'!$AE$9:$AE$55,MATCH($AL5+5,'Level Engine'!$AA$9:$AA$55,0)),0)))>='Level Engine'!$BG$85,ABS(N(IFERROR(INDEX('Level Engine'!$AE$9:$AE$55,MATCH($AL5,'Level Engine'!$AA$9:$AA$55,0)),0)))<='Level Engine'!$BG$88*ABS(N(IFERROR(INDEX('Level Engine'!$AE$9:$AE$55,MATCH($AL5+5,'Level Engine'!$AA$9:$AA$55,0)),0)))),AND(ABS(N(IFERROR(INDEX('Level Engine'!$AE$9:$AE$55,MATCH($AL5-5,'Level Engine'!$AA$9:$AA$55,0)),0)))>='Level Engine'!$BG$85,ABS(N(IFERROR(INDEX('Level Engine'!$AE$9:$AE$55,MATCH($AL5,'Level Engine'!$AA$9:$AA$55,0)),0)))<='Level Engine'!$BG$88*ABS(N(IFERROR(INDEX('Level Engine'!$AE$9:$AE$55,MATCH($AL5-5,'Level Engine'!$AA$9:$AA$55,0)),0)))))),IF(AND('King Node Model'!$A$8="Pos",N('Level Engine'!$BG$72)<>1),""," ∅"),""),"")&IF(IFERROR(INDEX('Level Engine'!$JD$9:$JD$55,MATCH($AL5,'Level Engine'!$AA$9:$AA$55,0)),"")="P"," P-OI",IF(IFERROR(INDEX('Level Engine'!$JD$9:$JD$55,MATCH($AL5,'Level Engine'!$AA$9:$AA$55,0)),"")="C"," C-OI","")) -> 7875 | C5: =IF(AND(ISNUMBER($AM5),$AM5>0,ISNUMBER($AO5),$AO$1>0),REPT("█",ROUND($AO5/$AO$1*26,0)),"") | D5: =IF(NOT(ISNUMBER($AL5)),"",IF(IFERROR(INDEX('Level Engine'!$FS$9:$FS$55,MATCH($AL5,'Level Engine'!$AA$9:$AA$55,0)),0)=1,"⊙","")) | E5: ="IV REGIME "&'King Node Model'!$P$9 -> IV REGIME Recovery Day with Local Wiggle | K5: =IF(ISNUMBER(SEARCH("Coiled Spring",'King Node Model'!$P$9)),"VIX "&'King Node Model'!$P$4&" VVIX "&'King Node Model'!$P$5&" → "&IF(AND('King Node Model'!$P$4="Up",'King Node Model'!$P$5="Up"),"High",IF(AND('King Node Model'!$P$4="Down",'King Node Model'!$P$5="Down"),"Low","MIXED")),"") | M5: =IF($L$5<>"",UPPER($L$5)&" IV (override)",IF('King Node Model'!$P$10="MIXED","MIXED IV — set override",IF('King Node Model'!$L$5="","",UPPER('King Node Model'!$L$5)&" IV"))) -> LOW IV | Q5: =PROPER('King Node Model'!$L$5) -> Low | R5: =(IF('Level Engine'!$D$5="UP","Rising",IF('Level Engine'!$D$5="DOWN","Falling","Flat")))&IF('Level Engine'!$BG$80<>""," (fast: "&IF(UPPER('Level Engine'!$BG$80)="UP","Rising",IF(UPPER('Level Engine'!$BG$80)="DOWN","Falling","Flat"))&")","") -> Rising (fast: Rising) | S5: =IF(ISNUMBER('Level Engine'!$C$3),'Level Engine'!$C$3,"") -> 0.137 | AL5: ='King Node Model'!A31 -> 7875 | AM5: ='King Node Model'!C31 -> 55016 | AN5: ='King Node Model'!T25 -> 7795 | AO5: ='King Node Model'!B31 -> 57578 | AY5: =IF(AND($B$2="Hide unsafe",$BB5=1),0,IF(AND(OR(AND(AND(ISNUMBER($AL5),OR(AND($AL5>=$AQ$22,$AL5<=$AR$22,$AS$22=1),$AL5=$AQ$22,$AL5=$AR$22,$AL5=$AQ$23,$AL5=$AR$23,$AL5=$AQ$24,$AL5=$AR$24),NOT(OR($AL5=$AN$5,$AL5=$AN$6,$AL5=$AN$7,$AL5=$AN$8,$AL5=$AN$10,$AL5=$AN$11))),NOT(OR(AND('King Node Model'!$P$13="Up",OR($AL5=$AQ$22,$AL5=$AQ$23,$AL5=$AQ$24,$AL5='King Node Model'!$AM$20,$AL5='King Node Model'!$AM$21,$AL5='King Node Model'!$AM$22),OR(AND('King Node Model'!$B$23-$AL5>=0,'King Node Model'!$B$23-$AL5<=5),AND('King Node Model'!$C$23-$AL5>=0,'King Node Model'!$C$23-$AL5<=5))),AND('King Node Model'!$P$13="Down",OR($AL5=$AR$22,$AL5=$AR$23,$AL5=$AR$24,$AL5='King Node Model'!$AN$20,$AL5='King Node Model'!$AN$21,$AL5='King Node Model'!$AN$22),OR(AND($AL5-'King Node Model'!$B$23>=0,$AL5-'King Node Model'!$B$23<=5),AND($AL5-'King Node Model'!$C$24>=0,$AL5-'King Node Model'!$C$24<=5)))))),AND(AND(ISNUMBER($AL5),OR(AND($AL5>=$AQ$22,$AL5<=$AR$22,$AS$22=1),$AL5=$AQ$22,$AL5=$AR$22,$AL5=$AQ$23,$AL5=$AR$23,$AL5=$AQ$24,$AL5=$AR$24,$AL5='King Node Model'!$AL$42,$AL5='King Node Model'!$AL$43),OR($AL5=$AN$5,$AL5=$AN$6,$AL5=$AN$7,$AL5=$AN$8,$AL5=$AN$10,$AL5=$AN$11)),NOT(OR(AND('King Node Model'!$P$13="Up",OR($AL5=$AQ$22,$AL5=$AQ$23,$AL5=$AQ$24,$AL5='King Node Model'!$AM$20,$AL5='King Node Model'!$AM$21,$AL5='King Node Model'!$AM$22),OR(AND('King Node Model'!$B$23-$AL5>=0,'King Node Model'!$B$23-$AL5<=5),AND('King Node Model'!$C$23-$AL5>=0,'King Node Model'!$C$23-$AL5<=5))),AND('King Node Model'!$P$13="Down",OR($AL5=$AR$22,$AL5=$AR$23,$AL5=$AR$24,$AL5='King Node Model'!$AN$20,$AL5='King Node Model'!$AN$21,$AL5='King Node Model'!$AN$22),OR(AND($AL5-'King Node Model'!$B$23>=0,$AL5-'King Node Model'!$B$23<=5),AND($AL5-'King Node Model'!$C$24>=0,$AL5-'King Node Model'!$C$24<=5)))))),AND(AND(ISNUMBER($AL5),OR(AND($AL5>='King Node Model'!$AM$20,$AL5<='King Node Model'!$AN$20,$AS$23=1),$AL5='King Node Model'!$AM$20,$AL5='King Node Model'!$AN$20,$AL5='King Node Model'!$AM$21,$AL5='King Node Model'!$AN$21,$AL5='King Node Model'!$AM$22,$AL5='King Node Model'!$AN$22),NOT(OR($AL5=$AN$5,$AL5=$AN$6,$AL5=$AN$7,$AL5=$AN$8,$AL5=$AN$10,$AL5=$AN$11))),NOT(AND(ISNUMBER('King Node Model'!$F$24),$AL5='King Node Model'!$F$24,IFERROR(INDEX('Level Engine'!$JN$9:$JN$55,MATCH($AL5,'Level Engine'!$AA$9:$AA$55,0)),0)<>1))),AND(AND(ISNUMBER($AL5),OR(AND($AL5>='King Node Model'!$AM$20,$AL5<='King Node Model'!$AN$20,$AS$23=1),$AL5='King Node Model'!$AM$20,$AL5='King Node Model'!$AN$20,$AL5='King Node Model'!$AM$21,$AL5='King Node Model'!$AN$21,$AL5='King Node Model'!$AM$22,$AL5='King Node Model'!$AN$22,$AL5='King Node Model'!$AL$49,$AL5='King Node Model'!$AL$50),OR($AL5=$AN$5,$AL5=$AN$6,$AL5=$AN$7,$AL5=$AN$8,$AL5=$AN$10,$AL5=$AN$11)),NOT(OR(AND('King Node Model'!$P$13="Up",OR($AL5=$AQ$22,$AL5=$AQ$23,$AL5=$AQ$24,$AL5='King Node Model'!$AM$20,$AL5='King Node Model'!$AM$21,$AL5='King Node Model'!$AM$22),OR(AND('King Node Model'!$B$23-$AL5>=0,'King Node Model'!$B$23-$AL5<=5),AND('King Node Model'!$C$23-$AL5>=0,'King Node Model'!$C$23-$AL5<=5))),AND('King Node Model'!$P$13="Down",OR($AL5=$AR$22,$AL5=$AR$23,$AL5=$AR$24,$AL5='King Node Model'!$AN$20,$AL5='King Node Model'!$AN$21,$AL5='King Node Model'!$AN$22),OR(AND($AL5-'King Node Model'!$B$23>=0,$AL5-'King Node Model'!$B$23<=5),AND($AL5-'King Node Model'!$C$24>=0,$AL5-'King Node Model'!$C$24<=5))))))),OR(COUNTIF('Level Engine'!$W$9:$W$14,$AL5)>0,COUNTIF('Level Engine'!$W$18:$W$23,$AL5)>0)),1,0)) -> 0 | AZ5: =IF($B$2="Hide unsafe",0,$BB5) -> 0 | BB5: =IF(OR(AND($AL5='King Node Model'!$AL$42,$AP$45<>"RASP"),AND($AL5='King Node Model'!$AL$43,$AP$46<>"RASP"),AND($AL5='King Node Model'!$AL$49,$AP$52<>"RASP"),AND($AL5='King Node Model'!$AL$50,$AP$53<>"RASP"),AND($AL5='King Node Model'!$AL$44,$AP$47<>"RASP"),AND($AL5='King Node Model'!$AL$51,$AP$54<>"RASP")),0,IF(AND(AND(ISNUMBER($AL5),OR(AND($AL5>=$AQ$22,$AL5<=$AR$22,$AP$45="RASP"),AND($AL5>=$AQ$23,$AL5<=$AR$23,$AP$46="RASP"),AND($AL5>=$AQ$24,$AL5<=$AR$24,$AP$47="RASP"),AND($AL5>='King Node Model'!$AM$20,$AL5<='King Node Model'!$AN$20,$AP$52="RASP",NOT($L$52=$AW$52)),AND($AL5='King Node Model'!$B$23,$AP$52="RASP",$L$52=$AW$52),AND($AL5>='King Node Model'!$AM$21,$AL5<='King Node Model'!$AN$21,$AP$53="RASP",NOT($L$53=$AW$53)),AND($AL5='King Node Model'!$B$23,$AP$53="RASP",$L$53=$AW$53),AND($AL5>='King Node Model'!$AM$22,$AL5<='King Node Model'!$AN$22,$AP$54="RASP"),AND($AL5>=IFERROR(INDEX('Level Engine'!$AT$9:$AT$55,MATCH('King Node Model'!$AL$42,'Level Engine'!$AA$9:$AA$55,0)),""),$AL5<=IFERROR(INDEX('Level Engine'!$AU$9:$AU$55,MATCH('King Node Model'!$AL$42,'Level Engine'!$AA$9:$AA$55,0)),""),$AP$45="RASP"),AND($AL5>=IFERROR(INDEX('Level Engine'!$AT$9:$AT$55,MATCH('King Node Model'!$AL$43,'Level Engine'!$AA$9:$AA$55,0)),""),$AL5<=IFERROR(INDEX('Level Engine'!$AU$9:$AU$55,MATCH('King Node Model'!$AL$43,'Level Engine'!$AA$9:$AA$55,0)),""),$AP$46="RASP"),AND($AL5>=IFERROR(INDEX('Level Engine'!$AT$9:$AT$55,MATCH('King Node Model'!$AL$44,'Level Engine'!$AA$9:$AA$55,0)),""),$AL5<=IFERROR(INDEX('Level Engine'!$AU$9:$AU$55,MATCH('King Node Model'!$AL$44,'Level Engine'!$AA$9:$AA$55,0)),""),$AP$47="RASP"),AND($AL5>=IFERROR(INDEX('Level Engine'!$AT$9:$AT$55,MATCH('King Node Model'!$AL$49,'Level Engine'!$AA$9:$AA$55,0)),""),$AL5<=IFERROR(INDEX('Level Engine'!$AU$9:$AU$55,MATCH('King Node Model'!$AL$49,'Level Engine'!$AA$9:$AA$55,0)),""),$AP$52="RASP",NOT($L$52=$AW$52)),AND($AL5>=IFERROR(INDEX('Level Engine'!$AT$9:$AT$55,MATCH('King Node Model'!$AL$50,'Level Engine'!$AA$9:$AA$55,0)),""),$AL5<=IFERROR(INDEX('Level Engine'!$AU$9:$AU$55,MATCH('King Node Model'!$AL$50,'Level Engine'!$AA$9:$AA$55,0)),""),$AP$53="RASP",NOT($L$53=$AW$53)),AND($AL5>=IFERROR(INDEX('Level Engine'!$AT$9:$AT$55,MATCH('King Node Model'!$AL$51,'Level Engine'!$AA$9:$AA$55,0)),""),$AL5<=IFERROR(INDEX('Level Engine'!$AU$9:$AU$55,MATCH('King Node Model'!$AL$51,'Level Engine'!$AA$9:$AA$55,0)),""),$AP$54="RASP"))),NOT(AND(ISNUMBER('King Node Model'!$F$24),$AL5='King Node Model'!$F$24,IFERROR(INDEX('Level Engine'!$JN$9:$JN$55,MATCH($AL5,'Level Engine'!$AA$9:$AA$55,0)),0)<>1,$AL5<>'King Node Model'!$AL$42,$AL5<>'King Node Model'!$AL$43,$AL5<>'King Node Model'!$AL$44,$AL5<>'King Node Model'!$AL$49,$AL5<>'King Node Model'!$AL$50,$AL5<>'King Node Model'!$AL$51))),1,0)) -> 0 | CO5: =IF(NOT(ISNUMBER($AL5)),"",IF(NOT(ISNUMBER(IFERROR(INDEX('Level Engine'!$FT$9:$FT$55,MATCH($AL5,'Level Engine'!$AA$9:$AA$55,0)),""))),"",IF(IFERROR(INDEX('Level Engine'!$FT$9:$FT$55,MATCH($AL5,'Level Engine'!$AA$9:$AA$55,0)),"")<0,0,2)+IF(ABS(IFERROR(INDEX('Level Engine'!$FT$9:$FT$55,MATCH($AL5,'Level Engine'!$AA$9:$AA$55,0)),""))>='Level Engine'!$FT$2,2,1))) -> 4 | DJ5: =IF(ISNUMBER($AL5),IF($AL5='Level Engine'!$BG$122," ⫪","")&IF($AL5='Level Engine'!$BG$118," S↑"&IFERROR(INDEX('Level Engine'!$MV$9:$MV$55,MATCH($AL5,'Level Engine'!$AA$9:$AA$55,0)),""),"")&IF($AL5='Level Engine'!$BG$119," S↓"&IFERROR(INDEX('Level Engine'!$MV$9:$MV$55,MATCH($AL5,'Level Engine'!$AA$9:$AA$55,0)),""),"")&IF($AL5='Level Engine'!$BG$120," D↑","")&IF($AL5='Level Engine'!$BG$121," D↓","")&IFERROR(INDEX('Level Engine'!$LG$9:$LG$55,MATCH($AL5,'Level Engine'!$AA$9:$AA$55,0)),"")&IF(IFERROR(INDEX('Level Engine'!$MA$9:$MA$55,MATCH($AL5,'Level Engine'!$AA$9:$AA$55,0)),0)=1," SAND","")&IF(IFERROR(INDEX('Level Engine'!$LM$9:$LM$55,MATCH($AL5,'Level Engine'!$AA$9:$AA$55,0)),0)>0," TP","")&IFERROR(" r"&MATCH($AL5,'Level Engine'!$W$9:$W$14,0),IFERROR(" s"&MATCH($AL5,'Level Engine'!$W$18:$W$23,0),""))&IF($AL5='Level Engine'!$BG$165," ◇","")&IF(N($DZ5)=1,IF($AL5>'Level Engine'!$BG$165," ⚠ DOM↓"," ⚠ DOM↑")&'Level Engine'!$BG$165,""),"") | DK5: =IF(AND(ISNUMBER($AL5),OR($AL5='King Node Model'!$AL$42,$AL5='King Node Model'!$AL$43,$AL5='King Node Model'!$AL$44)),IFERROR(MATCH($AL5,'Level Engine'!$W$9:$W$14,0),""),"") | DL5: =IF(AND(ISNUMBER($AL5),OR($AL5='King Node Model'!$AL$49,$AL5='King Node Model'!$AL$50,$AL5='King Node Model'!$AL$51)),IFERROR(MATCH($AL5,'Level Engine'!$W$18:$W$23,0),""),"") | DM5: =IF(AND(ISNUMBER($AL5),IFERROR(INDEX('Level Engine'!$LC$9:$LC$55,MATCH($AL5,'Level Engine'!$AA$9:$AA$55,0)),0)=1,OR($AL5=$AN$3,IFERROR(INDEX('Level Engine'!$LB$9:$LB$55,MATCH($AL5,'Level Engine'!$AA$9:$AA$55,0)),0)=1)),1,0) -> 0 | DZ5: =IF(ISNUMBER($AL5),IF(IFERROR(INDEX('Level Engine'!$NJ$9:$NJ$55,MATCH($AL5,'Level Engine'!$AA$9:$AA$55,0)),0)=1,1,0),0)
